[2023-12-12 02:40:31,845] {taskinstance.py:1179} INFO - Dependencies all met for <TaskInstance: Entregable3_Chumbita.cargar_data manual__2023-12-12T02:25:03.428441+00:00 [queued]>
[2023-12-12 02:40:31,983] {taskinstance.py:1179} INFO - Dependencies all met for <TaskInstance: Entregable3_Chumbita.cargar_data manual__2023-12-12T02:25:03.428441+00:00 [queued]>
[2023-12-12 02:40:31,989] {taskinstance.py:1376} INFO - 
--------------------------------------------------------------------------------
[2023-12-12 02:40:31,991] {taskinstance.py:1377} INFO - Starting attempt 4 of 6
[2023-12-12 02:40:31,991] {taskinstance.py:1378} INFO - 
--------------------------------------------------------------------------------
[2023-12-12 02:40:32,029] {taskinstance.py:1397} INFO - Executing <Task(PythonOperator): cargar_data> on 2023-12-12 02:25:03.428441+00:00
[2023-12-12 02:40:32,041] {standard_task_runner.py:52} INFO - Started process 817 to run task
[2023-12-12 02:40:32,049] {standard_task_runner.py:79} INFO - Running: ['***', 'tasks', 'run', 'Entregable3_Chumbita', 'cargar_data', 'manual__2023-12-12T02:25:03.428441+00:00', '--job-id', '22', '--raw', '--subdir', 'DAGS_FOLDER/ETL_Entregable3_Chumbita.py', '--cfg-path', '/tmp/tmpxdvkamlq', '--error-file', '/tmp/tmp0i_px4wx']
[2023-12-12 02:40:32,052] {standard_task_runner.py:80} INFO - Job 22: Subtask cargar_data
[2023-12-12 02:40:32,180] {task_command.py:371} INFO - Running <TaskInstance: Entregable3_Chumbita.cargar_data manual__2023-12-12T02:25:03.428441+00:00 [running]> on host 02fb1b542166
[2023-12-12 02:40:32,256] {logging_mixin.py:115} WARNING - /home/***/.local/lib/python3.7/site-packages/***/utils/context.py:202 AirflowContextDeprecationWarning: Accessing 'execution_date' from the template is deprecated and will be removed in a future version. Please use 'data_interval_start' or 'logical_date' instead.
[2023-12-12 02:40:32,327] {taskinstance.py:1591} INFO - Exporting the following env vars:
AIRFLOW_CTX_DAG_OWNER=ArielChumbita
AIRFLOW_CTX_DAG_ID=Entregable3_Chumbita
AIRFLOW_CTX_TASK_ID=cargar_data
AIRFLOW_CTX_EXECUTION_DATE=2023-12-12T02:25:03.428441+00:00
AIRFLOW_CTX_TRY_NUMBER=4
AIRFLOW_CTX_DAG_RUN_ID=manual__2023-12-12T02:25:03.428441+00:00
[2023-12-12 02:40:32,329] {logging_mixin.py:115} INFO - Cargando la data para la fecha: 2023-12-12 2
[2023-12-12 02:40:32,361] {logging_mixin.py:115} INFO - (3, 18)
[2023-12-12 02:40:32,422] {logging_mixin.py:115} INFO -    mining_algo  ...                            Date
0      SHA-256  ...  2023-12-12T02:24:25.073783104Z
1  mining_algo  ...                            Date
2      SHA-256  ...  2023-12-12T02:25:08.680354225Z

[3 rows x 18 columns]
[2023-12-12 02:40:34,632] {taskinstance.py:1909} ERROR - Task failed with exception
Traceback (most recent call last):
  File "/home/airflow/.local/lib/python3.7/site-packages/airflow/operators/python.py", line 171, in execute
    return_value = self.execute_callable()
  File "/home/airflow/.local/lib/python3.7/site-packages/airflow/operators/python.py", line 189, in execute_callable
    return self.python_callable(*self.op_args, **self.op_kwargs)
  File "/opt/airflow/dags/ETL_Entregable3_Chumbita.py", line 141, in cargar_data
    execute_values(cur, insert_sql, values)
  File "/home/airflow/.local/lib/python3.7/site-packages/psycopg2/extras.py", line 1270, in execute_values
    cur.execute(b''.join(parts))
psycopg2.errors.UndefinedTable: relation "mining_data" does not exist

[2023-12-12 02:40:34,658] {taskinstance.py:1420} INFO - Marking task as UP_FOR_RETRY. dag_id=Entregable3_Chumbita, task_id=cargar_data, execution_date=20231212T022503, start_date=20231212T024031, end_date=20231212T024034
[2023-12-12 02:40:34,690] {standard_task_runner.py:97} ERROR - Failed to execute job 22 for task cargar_data (relation "mining_data" does not exist
; 817)
[2023-12-12 02:40:34,715] {local_task_job.py:156} INFO - Task exited with return code 1
[2023-12-12 02:40:34,787] {local_task_job.py:273} INFO - 0 downstream tasks scheduled from follow-on schedule check
