[2023-12-29 04:30:15,750] {taskinstance.py:1032} INFO - Dependencies all met for <TaskInstance: data_sensors_AC.sensar_archivo manual__2023-12-29T04:29:43.330200+00:00 [queued]>
[2023-12-29 04:30:15,884] {taskinstance.py:1032} INFO - Dependencies all met for <TaskInstance: data_sensors_AC.sensar_archivo manual__2023-12-29T04:29:43.330200+00:00 [queued]>
[2023-12-29 04:30:15,896] {taskinstance.py:1238} INFO - 
--------------------------------------------------------------------------------
[2023-12-29 04:30:15,906] {taskinstance.py:1239} INFO - Starting attempt 1 of 1
[2023-12-29 04:30:15,908] {taskinstance.py:1240} INFO - 
--------------------------------------------------------------------------------
[2023-12-29 04:30:16,052] {taskinstance.py:1259} INFO - Executing <Task(FileSensor): sensar_archivo> on 2023-12-29 04:29:43.330200+00:00
[2023-12-29 04:30:16,072] {standard_task_runner.py:52} INFO - Started process 1870 to run task
[2023-12-29 04:30:16,142] {standard_task_runner.py:76} INFO - Running: ['***', 'tasks', 'run', 'data_sensors_AC', 'sensar_archivo', 'manual__2023-12-29T04:29:43.330200+00:00', '--job-id', '31', '--raw', '--subdir', 'DAGS_FOLDER/dag_sensors2.py', '--cfg-path', '/tmp/tmp4yv4ftdu', '--error-file', '/tmp/tmp7c0mgwni']
[2023-12-29 04:30:16,191] {standard_task_runner.py:77} INFO - Job 31: Subtask sensar_archivo
[2023-12-29 04:30:16,561] {logging_mixin.py:109} INFO - Running <TaskInstance: data_sensors_AC.sensar_archivo manual__2023-12-29T04:29:43.330200+00:00 [running]> on host 2762520f2c23
[2023-12-29 04:30:17,858] {taskinstance.py:1426} INFO - Exporting the following env vars:
AIRFLOW_CTX_DAG_OWNER=***
AIRFLOW_CTX_DAG_ID=data_sensors_AC
AIRFLOW_CTX_TASK_ID=sensar_archivo
AIRFLOW_CTX_EXECUTION_DATE=2023-12-29T04:29:43.330200+00:00
AIRFLOW_CTX_DAG_RUN_ID=manual__2023-12-29T04:29:43.330200+00:00
[2023-12-29 04:30:18,309] {taskinstance.py:1700} ERROR - Task failed with exception
Traceback (most recent call last):
  File "/home/airflow/.local/lib/python3.6/site-packages/airflow/models/taskinstance.py", line 1329, in _run_raw_task
    self._execute_task_with_callbacks(context)
  File "/home/airflow/.local/lib/python3.6/site-packages/airflow/models/taskinstance.py", line 1455, in _execute_task_with_callbacks
    result = self._execute_task(context, self.task)
  File "/home/airflow/.local/lib/python3.6/site-packages/airflow/models/taskinstance.py", line 1511, in _execute_task
    result = execute_callable(context=context)
  File "/home/airflow/.local/lib/python3.6/site-packages/airflow/sensors/base.py", line 234, in execute
    while not self.poke(context):
  File "/home/airflow/.local/lib/python3.6/site-packages/airflow/sensors/filesystem.py", line 56, in poke
    hook = FSHook(self.fs_conn_id)
  File "/home/airflow/.local/lib/python3.6/site-packages/airflow/hooks/filesystem.py", line 38, in __init__
    conn = self.get_connection(conn_id)
  File "/home/airflow/.local/lib/python3.6/site-packages/airflow/hooks/base.py", line 68, in get_connection
    conn = Connection.get_connection_from_secrets(conn_id)
  File "/home/airflow/.local/lib/python3.6/site-packages/airflow/models/connection.py", line 410, in get_connection_from_secrets
    raise AirflowNotFoundException(f"The conn_id `{conn_id}` isn't defined")
airflow.exceptions.AirflowNotFoundException: The conn_id `fs_default` isn't defined
[2023-12-29 04:30:18,671] {taskinstance.py:1277} INFO - Marking task as FAILED. dag_id=data_sensors_AC, task_id=sensar_archivo, execution_date=20231229T042943, start_date=20231229T043015, end_date=20231229T043018
[2023-12-29 04:30:18,993] {standard_task_runner.py:92} ERROR - Failed to execute job 31 for task sensar_archivo
Traceback (most recent call last):
  File "/home/airflow/.local/lib/python3.6/site-packages/airflow/task/task_runner/standard_task_runner.py", line 85, in _start_by_fork
    args.func(args, dag=self.dag)
  File "/home/airflow/.local/lib/python3.6/site-packages/airflow/cli/cli_parser.py", line 48, in command
    return func(*args, **kwargs)
  File "/home/airflow/.local/lib/python3.6/site-packages/airflow/utils/cli.py", line 92, in wrapper
    return f(*args, **kwargs)
  File "/home/airflow/.local/lib/python3.6/site-packages/airflow/cli/commands/task_command.py", line 298, in task_run
    _run_task_by_selected_method(args, dag, ti)
  File "/home/airflow/.local/lib/python3.6/site-packages/airflow/cli/commands/task_command.py", line 107, in _run_task_by_selected_method
    _run_raw_task(args, ti)
  File "/home/airflow/.local/lib/python3.6/site-packages/airflow/cli/commands/task_command.py", line 184, in _run_raw_task
    error_file=args.error_file,
  File "/home/airflow/.local/lib/python3.6/site-packages/airflow/utils/session.py", line 70, in wrapper
    return func(*args, session=session, **kwargs)
  File "/home/airflow/.local/lib/python3.6/site-packages/airflow/models/taskinstance.py", line 1329, in _run_raw_task
    self._execute_task_with_callbacks(context)
  File "/home/airflow/.local/lib/python3.6/site-packages/airflow/models/taskinstance.py", line 1455, in _execute_task_with_callbacks
    result = self._execute_task(context, self.task)
  File "/home/airflow/.local/lib/python3.6/site-packages/airflow/models/taskinstance.py", line 1511, in _execute_task
    result = execute_callable(context=context)
  File "/home/airflow/.local/lib/python3.6/site-packages/airflow/sensors/base.py", line 234, in execute
    while not self.poke(context):
  File "/home/airflow/.local/lib/python3.6/site-packages/airflow/sensors/filesystem.py", line 56, in poke
    hook = FSHook(self.fs_conn_id)
  File "/home/airflow/.local/lib/python3.6/site-packages/airflow/hooks/filesystem.py", line 38, in __init__
    conn = self.get_connection(conn_id)
  File "/home/airflow/.local/lib/python3.6/site-packages/airflow/hooks/base.py", line 68, in get_connection
    conn = Connection.get_connection_from_secrets(conn_id)
  File "/home/airflow/.local/lib/python3.6/site-packages/airflow/models/connection.py", line 410, in get_connection_from_secrets
    raise AirflowNotFoundException(f"The conn_id `{conn_id}` isn't defined")
airflow.exceptions.AirflowNotFoundException: The conn_id `fs_default` isn't defined
[2023-12-29 04:30:19,137] {local_task_job.py:154} INFO - Task exited with return code 1
[2023-12-29 04:30:19,486] {local_task_job.py:264} INFO - 0 downstream tasks scheduled from follow-on schedule check
