[2023-12-24 19:37:41,248] {taskinstance.py:1179} INFO - Dependencies all met for <TaskInstance: Bitcoin_ETL.cargar_data manual__2023-12-24T19:27:14.276038+00:00 [queued]>
[2023-12-24 19:37:41,271] {taskinstance.py:1179} INFO - Dependencies all met for <TaskInstance: Bitcoin_ETL.cargar_data manual__2023-12-24T19:27:14.276038+00:00 [queued]>
[2023-12-24 19:37:41,271] {taskinstance.py:1376} INFO - 
--------------------------------------------------------------------------------
[2023-12-24 19:37:41,272] {taskinstance.py:1377} INFO - Starting attempt 3 of 6
[2023-12-24 19:37:41,273] {taskinstance.py:1378} INFO - 
--------------------------------------------------------------------------------
[2023-12-24 19:37:41,306] {taskinstance.py:1397} INFO - Executing <Task(PythonOperator): cargar_data> on 2023-12-24 19:27:14.276038+00:00
[2023-12-24 19:37:41,320] {standard_task_runner.py:52} INFO - Started process 616 to run task
[2023-12-24 19:37:41,325] {standard_task_runner.py:79} INFO - Running: ['***', 'tasks', 'run', 'Bitcoin_ETL', 'cargar_data', 'manual__2023-12-24T19:27:14.276038+00:00', '--job-id', '11', '--raw', '--subdir', 'DAGS_FOLDER/ETL_Bitcoin.py', '--cfg-path', '/tmp/tmpp4enr7lw', '--error-file', '/tmp/tmptr2hq2ry']
[2023-12-24 19:37:41,328] {standard_task_runner.py:80} INFO - Job 11: Subtask cargar_data
[2023-12-24 19:37:41,448] {task_command.py:371} INFO - Running <TaskInstance: Bitcoin_ETL.cargar_data manual__2023-12-24T19:27:14.276038+00:00 [running]> on host 3331eab26945
[2023-12-24 19:37:41,529] {logging_mixin.py:115} WARNING - /home/***/.local/lib/python3.7/site-packages/***/utils/context.py:202 AirflowContextDeprecationWarning: Accessing 'execution_date' from the template is deprecated and will be removed in a future version. Please use 'data_interval_start' or 'logical_date' instead.
[2023-12-24 19:37:41,624] {taskinstance.py:1591} INFO - Exporting the following env vars:
AIRFLOW_CTX_DAG_OWNER=ArielChumbita
AIRFLOW_CTX_DAG_ID=Bitcoin_ETL
AIRFLOW_CTX_TASK_ID=cargar_data
AIRFLOW_CTX_EXECUTION_DATE=2023-12-24T19:27:14.276038+00:00
AIRFLOW_CTX_TRY_NUMBER=3
AIRFLOW_CTX_DAG_RUN_ID=manual__2023-12-24T19:27:14.276038+00:00
[2023-12-24 19:37:41,627] {logging_mixin.py:115} INFO - Cargando la data para la fecha: 2023-12-24 19
[2023-12-24 19:37:41,656] {logging_mixin.py:115} INFO - (3, 18)
[2023-12-24 19:37:41,712] {logging_mixin.py:115} INFO -    mining_algo  ...                            Date
0      SHA-256  ...  2023-12-24T19:27:22.060801782Z
1  mining_algo  ...                            Date
2      SHA-256  ...  2023-12-24T19:35:35.490783954Z

[3 rows x 18 columns]
[2023-12-24 19:37:43,486] {taskinstance.py:1909} ERROR - Task failed with exception
Traceback (most recent call last):
  File "/home/airflow/.local/lib/python3.7/site-packages/airflow/operators/python.py", line 171, in execute
    return_value = self.execute_callable()
  File "/home/airflow/.local/lib/python3.7/site-packages/airflow/operators/python.py", line 189, in execute_callable
    return self.python_callable(*self.op_args, **self.op_kwargs)
  File "/opt/airflow/dags/ETL_Bitcoin.py", line 119, in cargar_data
    port='5439')
  File "/home/airflow/.local/lib/python3.7/site-packages/psycopg2/__init__.py", line 122, in connect
    conn = _connect(dsn, connection_factory=connection_factory, **kwasync)
psycopg2.OperationalError: connection to server at "data-engineer-cluster.cyhh5bfevlmn.us-east-1.redshift.amazonaws.com" (52.44.43.227), port 5439 failed: FATAL:  password authentication failed for user "ariel_chumbita_coderhouse"
connection to server at "data-engineer-cluster.cyhh5bfevlmn.us-east-1.redshift.amazonaws.com" (52.44.43.227), port 5439 failed: FATAL:  password authentication failed for user "ariel_chumbita_coderhouse"

[2023-12-24 19:37:43,509] {taskinstance.py:1420} INFO - Marking task as UP_FOR_RETRY. dag_id=Bitcoin_ETL, task_id=cargar_data, execution_date=20231224T192714, start_date=20231224T193741, end_date=20231224T193743
[2023-12-24 19:37:43,531] {standard_task_runner.py:97} ERROR - Failed to execute job 11 for task cargar_data (connection to server at "data-engineer-cluster.cyhh5bfevlmn.us-east-1.redshift.amazonaws.com" (52.44.43.227), port 5439 failed: FATAL:  password authentication failed for user "ariel_chumbita_coderhouse"
connection to server at "data-engineer-cluster.cyhh5bfevlmn.us-east-1.redshift.amazonaws.com" (52.44.43.227), port 5439 failed: FATAL:  password authentication failed for user "ariel_chumbita_coderhouse"
; 616)
[2023-12-24 19:37:43,552] {local_task_job.py:156} INFO - Task exited with return code 1
[2023-12-24 19:37:43,607] {local_task_job.py:273} INFO - 0 downstream tasks scheduled from follow-on schedule check
