[2023-12-12 02:49:15,572] {taskinstance.py:1179} INFO - Dependencies all met for <TaskInstance: Entregable3_Chumbita.cargar_data scheduled__2023-12-11T00:00:00+00:00 [queued]>
[2023-12-12 02:49:15,591] {taskinstance.py:1179} INFO - Dependencies all met for <TaskInstance: Entregable3_Chumbita.cargar_data scheduled__2023-12-11T00:00:00+00:00 [queued]>
[2023-12-12 02:49:15,591] {taskinstance.py:1376} INFO - 
--------------------------------------------------------------------------------
[2023-12-12 02:49:15,593] {taskinstance.py:1377} INFO - Starting attempt 6 of 6
[2023-12-12 02:49:15,594] {taskinstance.py:1378} INFO - 
--------------------------------------------------------------------------------
[2023-12-12 02:49:15,621] {taskinstance.py:1397} INFO - Executing <Task(PythonOperator): cargar_data> on 2023-12-11 00:00:00+00:00
[2023-12-12 02:49:15,633] {standard_task_runner.py:52} INFO - Started process 1111 to run task
[2023-12-12 02:49:15,639] {standard_task_runner.py:79} INFO - Running: ['***', 'tasks', 'run', 'Entregable3_Chumbita', 'cargar_data', 'scheduled__2023-12-11T00:00:00+00:00', '--job-id', '26', '--raw', '--subdir', 'DAGS_FOLDER/ETL_Entregable3_Chumbita.py', '--cfg-path', '/tmp/tmphi3a3wkg', '--error-file', '/tmp/tmps52mhufa']
[2023-12-12 02:49:15,641] {standard_task_runner.py:80} INFO - Job 26: Subtask cargar_data
[2023-12-12 02:49:15,752] {task_command.py:371} INFO - Running <TaskInstance: Entregable3_Chumbita.cargar_data scheduled__2023-12-11T00:00:00+00:00 [running]> on host 02fb1b542166
[2023-12-12 02:49:15,839] {logging_mixin.py:115} WARNING - /home/***/.local/lib/python3.7/site-packages/***/utils/context.py:202 AirflowContextDeprecationWarning: Accessing 'execution_date' from the template is deprecated and will be removed in a future version. Please use 'data_interval_start' or 'logical_date' instead.
[2023-12-12 02:49:15,935] {taskinstance.py:1591} INFO - Exporting the following env vars:
AIRFLOW_CTX_DAG_OWNER=ArielChumbita
AIRFLOW_CTX_DAG_ID=Entregable3_Chumbita
AIRFLOW_CTX_TASK_ID=cargar_data
AIRFLOW_CTX_EXECUTION_DATE=2023-12-11T00:00:00+00:00
AIRFLOW_CTX_TRY_NUMBER=6
AIRFLOW_CTX_DAG_RUN_ID=scheduled__2023-12-11T00:00:00+00:00
[2023-12-12 02:49:15,938] {logging_mixin.py:115} INFO - Cargando la data para la fecha: 2023-12-11 0
[2023-12-12 02:49:15,970] {logging_mixin.py:115} INFO - (1, 18)
[2023-12-12 02:49:16,025] {logging_mixin.py:115} INFO -   mining_algo  ...                            Date
0     SHA-256  ...  2023-12-12T02:23:00.691131665Z

[1 rows x 18 columns]
[2023-12-12 02:49:17,901] {taskinstance.py:1909} ERROR - Task failed with exception
Traceback (most recent call last):
  File "/home/airflow/.local/lib/python3.7/site-packages/airflow/operators/python.py", line 171, in execute
    return_value = self.execute_callable()
  File "/home/airflow/.local/lib/python3.7/site-packages/airflow/operators/python.py", line 189, in execute_callable
    return self.python_callable(*self.op_args, **self.op_kwargs)
  File "/opt/airflow/dags/ETL_Entregable3_Chumbita.py", line 141, in cargar_data
    execute_values(cur, insert_sql, values)
  File "/home/airflow/.local/lib/python3.7/site-packages/psycopg2/extras.py", line 1270, in execute_values
    cur.execute(b''.join(parts))
psycopg2.errors.UndefinedTable: relation "mining_data" does not exist

[2023-12-12 02:49:17,926] {taskinstance.py:1420} INFO - Marking task as FAILED. dag_id=Entregable3_Chumbita, task_id=cargar_data, execution_date=20231211T000000, start_date=20231212T024915, end_date=20231212T024917
[2023-12-12 02:49:17,952] {standard_task_runner.py:97} ERROR - Failed to execute job 26 for task cargar_data (relation "mining_data" does not exist
; 1111)
[2023-12-12 02:49:17,987] {local_task_job.py:156} INFO - Task exited with return code 1
[2023-12-12 02:49:18,056] {local_task_job.py:273} INFO - 0 downstream tasks scheduled from follow-on schedule check
